2016-01-25 16:00:07,729 (39765/MainThread) pgcli.main ERROR - traceback: 'Traceback (most recent call last):\n  File "/usr/local/Cellar/pgcli/0.20.1/libexec/lib/python2.7/site-packages/pgcli/main.py", line 235, in connect\n    raise e\nOperationalError: could not connect to server: No such file or directory\n\tIs the server running locally and accepting\n\tconnections on Unix domain socket "/tmp/.s.PGSQL.5432"?\n\n'
2016-02-13 10:52:37,381 (44876/MainThread) pgcli.main ERROR - traceback: 'Traceback (most recent call last):\n  File "/usr/local/Cellar/pgcli/0.20.1/libexec/lib/python2.7/site-packages/pgcli/main.py", line 235, in connect\n    raise e\nOperationalError: could not connect to server: No such file or directory\n\tIs the server running locally and accepting\n\tconnections on Unix domain socket "/tmp/.s.PGSQL.5432"?\n\n'
2016-02-13 10:53:06,033 (44915/MainThread) pgcli.main ERROR - traceback: 'Traceback (most recent call last):\n  File "/usr/local/Cellar/pgcli/0.20.1/libexec/lib/python2.7/site-packages/pgcli/main.py", line 235, in connect\n    raise e\nOperationalError: could not connect to server: No such file or directory\n\tIs the server running locally and accepting\n\tconnections on Unix domain socket "/tmp/.s.PGSQL.5432"?\n\n'
2016-02-13 10:53:15,911 (44928/MainThread) pgcli.main ERROR - traceback: 'Traceback (most recent call last):\n  File "/usr/local/Cellar/pgcli/0.20.1/libexec/lib/python2.7/site-packages/pgcli/main.py", line 235, in connect\n    raise e\nOperationalError: could not connect to server: No such file or directory\n\tIs the server running locally and accepting\n\tconnections on Unix domain socket "/tmp/.s.PGSQL.5432"?\n\n'
2016-02-13 10:53:25,009 (44941/MainThread) pgcli.main ERROR - traceback: 'Traceback (most recent call last):\n  File "/usr/local/Cellar/pgcli/0.20.1/libexec/lib/python2.7/site-packages/pgcli/main.py", line 235, in connect\n    raise e\nOperationalError: could not connect to server: No such file or directory\n\tIs the server running locally and accepting\n\tconnections on Unix domain socket "/tmp/.s.PGSQL.5432"?\n\n'
2016-02-13 10:53:45,567 (44954/MainThread) pgcli.main ERROR - traceback: 'Traceback (most recent call last):\n  File "/usr/local/Cellar/pgcli/0.20.1/libexec/lib/python2.7/site-packages/pgcli/main.py", line 235, in connect\n    raise e\nOperationalError: could not connect to server: No such file or directory\n\tIs the server running locally and accepting\n\tconnections on Unix domain socket "/tmp/.s.PGSQL.5432"?\n\n'
2016-02-13 10:54:31,618 (44972/MainThread) pgcli.main ERROR - traceback: 'Traceback (most recent call last):\n  File "/usr/local/Cellar/pgcli/0.20.1/libexec/lib/python2.7/site-packages/pgcli/main.py", line 235, in connect\n    raise e\nOperationalError: could not connect to server: No such file or directory\n\tIs the server running locally and accepting\n\tconnections on Unix domain socket "/tmp/.s.PGSQL.5432"?\n\n'
2016-02-13 10:54:41,322 (44985/MainThread) pgcli.main ERROR - traceback: 'Traceback (most recent call last):\n  File "/usr/local/Cellar/pgcli/0.20.1/libexec/lib/python2.7/site-packages/pgcli/main.py", line 235, in connect\n    raise e\nOperationalError: FATAL:  role "johannes" does not exist\n\n'
2016-02-13 10:55:52,664 (44998/MainThread) pgcli.pgexecute ERROR - sql: u'SEL', error: ProgrammingError('syntax error at or near "SEL"\nLINE 1: SEL\n        ^\n',)
2016-02-13 10:55:52,667 (44998/MainThread) pgcli.pgexecute ERROR - traceback: 'Traceback (most recent call last):\n  File "/usr/local/Cellar/pgcli/0.20.1/libexec/lib/python2.7/site-packages/pgcli/pgexecute.py", line 266, in run\n    yield self.execute_normal_sql(sql) + (sql, True)\n  File "/usr/local/Cellar/pgcli/0.20.1/libexec/lib/python2.7/site-packages/pgcli/pgexecute.py", line 286, in execute_normal_sql\n    cur.execute(split_sql)\nProgrammingError: syntax error at or near "SEL"\nLINE 1: SEL\n        ^\n\n'
2016-03-07 09:12:26,076 (44792/MainThread) pgcli.main ERROR - traceback: 'Traceback (most recent call last):\n  File "/usr/local/Cellar/pgcli/0.20.1/libexec/lib/python2.7/site-packages/pgcli/main.py", line 235, in connect\n    raise e\nOperationalError: could not connect to server: No such file or directory\n\tIs the server running locally and accepting\n\tconnections on Unix domain socket "/tmp/.s.PGSQL.5432"?\n\n'
2016-03-18 14:29:36,754 (19996/MainThread) pgcli.main ERROR - traceback: 'Traceback (most recent call last):\n  File "/usr/local/Cellar/pgcli/0.20.1/libexec/lib/python2.7/site-packages/pgcli/main.py", line 235, in connect\n    raise e\nOperationalError: could not connect to server: No such file or directory\n\tIs the server running locally and accepting\n\tconnections on Unix domain socket "/tmp/.s.PGSQL.5432"?\n\n'
2016-03-18 14:30:07,889 (20028/MainThread) pgcli.main ERROR - traceback: 'Traceback (most recent call last):\n  File "/usr/local/Cellar/pgcli/0.20.1/libexec/lib/python2.7/site-packages/pgcli/main.py", line 235, in connect\n    raise e\nOperationalError: could not connect to server: No such file or directory\n\tIs the server running locally and accepting\n\tconnections on Unix domain socket "/tmp/.s.PGSQL.5432"?\n\n'
